Workbook

Sheet Executive Summary
A1: EXECUTIVE SUMMARY - 36-MONTH PROJECTION
A3: Metric | B3: Y1M1 | C3: Y1M2 | D3: Y1M3 | E3: Y1M4 | F3: Y1M5 | G3: Y1M6 | H3: Y1M7 | I3: Y1M8 | J3: Y1M9 | K3: Y1M10 | L3: Y1M11 | M3: Y1M12 | N3: Y2M1 | O3: Y2M2 | P3: Y2M3 | Q3: Y2M4 | R3: Y2M5 | S3: Y2M6 | T3: Y2M7 | U3: Y2M8 | V3: Y2M9 | W3: Y2M10 | X3: Y2M11 | Y3: Y2M12 | Z3: Y3M1 | AA3: Y3M2 | AB3: Y3M3 | AC3: Y3M4 | AD3: Y3M5 | AE3: Y3M6 | AF3: Y3M7 | AG3: Y3M8 | AH3: Y3M9 | AI3: Y3M10 | AJ3: Y3M11 | AK3: Y3M12
A4: SEAT AND ACCOUNT GROWTH
A5: New Seats | B5: ='Revenue Model'!B$27 -> 0 | C5: ='Revenue Model'!C$27 -> 0 | D5: ='Revenue Model'!D$27 -> 0 | E5: ='Revenue Model'!E$27 -> 242 | F5: ='Revenue Model'!F$27 -> 145 | G5: ='Revenue Model'!G$27 -> 218 | H5: ='Revenue Model'!H$27 -> 266 | I5: ='Revenue Model'!I$27 -> 266 | ... AK5: ='Revenue Model'!AK$27 -> 1505
A6: Active Seats (EOP) | B6: ='Revenue Model'!B$28 -> 0 | C6: ='Revenue Model'!C$28 -> 0 | D6: ='Revenue Model'!D$28 -> 0 | E6: ='Revenue Model'!E$28 -> 242 | F6: ='Revenue Model'!F$28 -> 386 | G6: ='Revenue Model'!G$28 -> 602 | H6: ='Revenue Model'!H$28 -> 866 | I6: ='Revenue Model'!I$28 -> 1129 | ... AK6: ='Revenue Model'!AK$28 -> 23091
A8: REVENUE
A9: MRR | B9: ='Revenue Model'!B$31 -> 0 | C9: ='Revenue Model'!C$31 -> 0 | D9: ='Revenue Model'!D$31 -> 0 | E9: ='Revenue Model'!E$31 -> 7150 | F9: ='Revenue Model'!F$31 -> 10709.503 | G9: ='Revenue Model'!G$31 -> 17899.835 | H9: ='Revenue Model'!H$31 -> 25452.586 | I9: ='Revenue Model'!I$31 -> 33182.414 | ... AK9: ='Revenue Model'!AK$31 -> 716489.77
A10: ARR (MRR x 12) | B10: ='Revenue Model'!B$32 -> 0 | C10: ='Revenue Model'!C$32 -> 0 | D10: ='Revenue Model'!D$32 -> 0 | E10: ='Revenue Model'!E$32 -> 85800 | F10: ='Revenue Model'!F$32 -> 128514.04 | G10: ='Revenue Model'!G$32 -> 214798.02 | H10: ='Revenue Model'!H$32 -> 305431.04 | I10: ='Revenue Model'!I$32 -> 398188.96 | ... AK10: ='Revenue Model'!AK$32 -> 8597877.2
A11: UNIT ECONOMICS
A12: Total COGS | B12: ='COGS Analysis'!B$20 -> 0 | C12: ='COGS Analysis'!C$20 -> 0 | D12: ='COGS Analysis'!D$20 -> 0 | E12: ='COGS Analysis'!E$20 -> 3193.93 | F12: ='COGS Analysis'!F$20 -> 3943.7156 | G12: ='COGS Analysis'!G$20 -> 5122.0752 | H12: ='COGS Analysis'!H$20 -> 6526.465 | I12: ='COGS Analysis'!I$20 -> 7931.5 | ... AK12: ='COGS Analysis'!AK$20 -> 88735.079
A13: Gross Margin % | B13: ='COGS Analysis'!B$23 -> 0 | C13: ='COGS Analysis'!C$23 -> 0 | D13: ='COGS Analysis'!D$23 -> 0 | E13: ='COGS Analysis'!E$23 -> 0.5532965 | F13: ='COGS Analysis'!F$23 -> 0.63175551 | G13: ='COGS Analysis'!G$23 -> 0.71384791 | H13: ='COGS Analysis'!H$23 -> 0.74358343 | I13: ='COGS Analysis'!I$23 -> 0.76097278 | ... AK13: ='COGS Analysis'!AK$23 -> 0.87615304
A14: PROFITABILITY
A15: EBITDA | B15: ='P&L Statement'!B$17 -> -68375 | C15: ='P&L Statement'!C$17 -> -62375 | D15: ='P&L Statement'!D$17 -> -62375 | E15: ='P&L Statement'!E$17 -> -87246.571 | F15: ='P&L Statement'!F$17 -> -83023.745 | G15: ='P&L Statement'!G$17 -> -81708.146 | H15: ='P&L Statement'!H$17 -> -75528.089 | I15: ='P&L Statement'!I$17 -> -78203.297 | ... AK15: ='P&L Statement'!AK$17 -> 232639.15
A16: EBITDA Margin % | B16: ='P&L Statement'!B$18 -> 0 | C16: ='P&L Statement'!C$18 -> 0 | D16: ='P&L Statement'!D$18 -> 0 | E16: ='P&L Statement'!E$18 -> -12.202318 | F16: ='P&L Statement'!F$18 -> -7.7523431 | G16: ='P&L Statement'!G$18 -> -4.564743 | H16: ='P&L Statement'!H$18 -> -2.9674033 | I16: ='P&L Statement'!I$18 -> -2.3567694 | ... AK16: ='P&L Statement'!AK$18 -> 0.32469291
A17: Headcount | B17: ='Staffing Plan'!F$33 -> 3 | C17: ='Staffing Plan'!G$33 -> 3 | D17: ='Staffing Plan'!H$33 -> 3 | E17: ='Staffing Plan'!I$33 -> 5 | F17: ='Staffing Plan'!J$33 -> 5 | G17: ='Staffing Plan'!K$33 -> 5 | H17: ='Staffing Plan'!L$33 -> 5 | I17: ='Staffing Plan'!M$33 -> 6 | ... AK17: ='Staffing Plan'!AO$33 -> 23
A19: ANNUAL SUMMARY
A20: Metric | B20: Year 1 | C20: Year 2 | D20: Year 3
A21: Ending ARR | B21: =M$9*12 -> 791761.09 | C21: =Y$9*12 -> 3310491.9 | D21: =AK$9*12 -> 8597877.2
A22: Ending Seats | B22: =M$6 -> 2247 | C22: =Y$6 -> 9022 | D22: =AK$6 -> 23091
A23: Gross Margin % | B23: ='COGS Analysis'!M$23 -> 0.78929322 | C23: ='COGS Analysis'!Y$23 -> 0.84102069 | D23: ='COGS Analysis'!AK$23 -> 0.87615304
A24: Ending EBITDA | B24: ='P&L Statement'!M$17 -> -64930.513 | C24: ='P&L Statement'!Y$17 -> -1698.3864 | D24: ='P&L Statement'!AK$17 -> 232639.15
A25: EBITDA Margin % | B25: ='P&L Statement'!M$18 -> -0.98409251 | C25: ='P&L Statement'!Y$18 -> -0.006156377 | D25: ='P&L Statement'!AK$18 -> 0.32469291
A26: Ending Headcount | B26: =M$17 -> 7 | C26: =Y$17 -> 13 | D26: =AK$17 -> 23
A27: New Accounts (Year) | B27: ='Revenue Model'!M$35 -> 238 | C27: ='Revenue Model'!Y$35-'Revenue Model'!M$35 -> 452 | D27: ='Revenue Model'!AK$35-'Revenue Model'!Y$35 -> 627
A28: YoY ARR Growth % | B28: N/A | C28: =(Y$9*12-M$9*12)/(M$9*12) -> 3.1811753 | D28: =(AK$9*12-Y$9*12)/(Y$9*12) -> 1.59716
A30: CASH & RUNWAY
A31: Seed Funding | B31: ='Model Inputs'!B83 -> 2500000 | C31: Runway (Months) | D31: ='P&L Statement'!B22 -> 36 | E31: Ending Cash | F31: ='P&L Statement'!AK21 -> 2266615
A33: Month | B33: M1 | C33: M2 | D33: M3 | E33: M4 | F33: M5 | G33: M6 | H33: M7 | I33: M8 | J33: M9 | K33: M10 | L33: M11 | M33: M12 | N33: M13 | O33: M14 | P33: M15 | Q33: M16 | R33: M17 | S33: M18 | T33: M19 | U33: M20 | V33: M21 | W33: M22 | X33: M23 | Y33: M24 | Z33: M25 | AA33: M26 | AB33: M27 | AC33: M28 | AD33: M29 | AE33: M30 | AF33: M31 | AG33: M32 | AH33: M33 | AI33: M34 | AJ33: M35 | AK33: M36
A34: Monthly EBITDA | B34: ='P&L Statement'!B17 -> -68375 | C34: ='P&L Statement'!C17 -> -62375 | D34: ='P&L Statement'!D17 -> -62375 | E34: ='P&L Statement'!E17 -> -87246.571 | F34: ='P&L Statement'!F17 -> -83023.745 | G34: ='P&L Statement'!G17 -> -81708.146 | H34: ='P&L Statement'!H17 -> -75528.089 | I34: ='P&L Statement'!I17 -> -78203.297 | ... AK34: ='P&L Statement'!AK17 -> 232639.15
A35: Cumulative EBITDA | B35: ='P&L Statement'!B20 -> -68375 | C35: ='P&L Statement'!C20 -> -130750 | D35: ='P&L Statement'!D20 -> -193125 | E35: ='P&L Statement'!E20 -> -280371.57 | F35: ='P&L Statement'!F20 -> -363395.32 | G35: ='P&L Statement'!G20 -> -445103.46 | H35: ='P&L Statement'!H20 -> -520631.55 | I35: ='P&L Statement'!I20 -> -598834.85 | ... AK35: ='P&L Statement'!AK20 -> -233385.05
A36: Cash Position | B36: ='P&L Statement'!B21 -> 2431625 | C36: ='P&L Statement'!C21 -> 2369250 | D36: ='P&L Statement'!D21 -> 2306875 | E36: ='P&L Statement'!E21 -> 2219628.4 | F36: ='P&L Statement'!F21 -> 2136604.7 | G36: ='P&L Statement'!G21 -> 2054896.5 | H36: ='P&L Statement'!H21 -> 1979368.4 | I36: ='P&L Statement'!I21 -> 1901165.2 | ... AK36: ='P&L Statement'!AK21 -> 2266615
A37: Status | B37: =IF(B36>500000,"OK",IF(B36>250000,"Watch",IF(B36>0,"Low","OUT"))) -> OK | C37: =IF(C36>500000,"OK",IF(C36>250000,"Watch",IF(C36>0,"Low","OUT"))) -> OK | D37: =IF(D36>500000,"OK",IF(D36>250000,"Watch",IF(D36>0,"Low","OUT"))) -> OK | E37: =IF(E36>500000,"OK",IF(E36>250000,"Watch",IF(E36>0,"Low","OUT"))) -> OK | F37: =IF(F36>500000,"OK",IF(F36>250000,"Watch",IF(F36>0,"Low","OUT"))) -> OK | G37: =IF(G36>500000,"OK",IF(G36>250000,"Watch",IF(G36>0,"Low","OUT"))) -> OK | H37: =IF(H36>500000,"OK",IF(H36>250000,"Watch",IF(H36>0,"Low","OUT"))) -> OK | I37: =IF(I36>500000,"OK",IF(I36>250000,"Watch",IF(I36>0,"Low","OUT"))) -> OK | ... AK37: =IF(AK36>500000,"OK",IF(AK36>250000,"Watch",IF(AK36>0,"Low","OUT"))) -> OK
A39: YEAR-END SUMMARY | B39: Y1 (M12) | C39: Y2 (M24) | D39: Y3 (M36)
A40: Year-End Cash | B40: ='P&L Statement'!M21 -> 1619778.4 | C40: ='P&L Statement'!Y21 -> 1014396.4 | D40: ='P&L Statement'!AK21 -> 2266615
A41: Year Cash Burn | B41: =SUM('P&L Statement'!B17:M17) -> -880221.57 | C41: =SUM('P&L Statement'!N17:Y17) -> -605382.01 | D41: =SUM('P&L Statement'!Z17:AK17) -> 1252218.5
A42: Year Low Point | B42: =MIN('P&L Statement'!B21:M21) -> 1619778.4 | C42: =MIN('P&L Statement'!N21:Y21) -> 1014396.4 | D42: =MIN('P&L Statement'!Z21:AK21) -> 999147.36

Sheet Revenue Model
A1: REVENUE MODEL - 36-MONTH BOTTOM-UP
A3: Metric | B3: Y1M1 | C3: Y1M2 | D3: Y1M3 | E3: Y1M4 | F3: Y1M5 | G3: Y1M6 | H3: Y1M7 | I3: Y1M8 | J3: Y1M9 | K3: Y1M10 | L3: Y1M11 | M3: Y1M12 | N3: Y2M1 | O3: Y2M2 | P3: Y2M3 | Q3: Y2M4 | R3: Y2M5 | S3: Y2M6 | T3: Y2M7 | U3: Y2M8 | V3: Y2M9 | W3: Y2M10 | X3: Y2M11 | Y3: Y2M12 | Z3: Y3M1 | AA3: Y3M2 | AB3: Y3M3 | AC3: Y3M4 | AD3: Y3M5 | AE3: Y3M6 | AF3: Y3M7 | AG3: Y3M8 | AH3: Y3M9 | AI3: Y3M10 | AJ3: Y3M11 | AK3: Y3M12
A4: SALES ACQUISITION (Verticals)
A5: Crypto/Web3 Accounts | B5: ='Model Inputs'!B192 -> 0 | C5: ='Model Inputs'!C192 -> 0 | D5: ='Model Inputs'!D192 -> 0 | E5: ='Model Inputs'!E192 -> 8 | F5: ='Model Inputs'!F192 -> 6 | G5: ='Model Inputs'!G192 -> 7 | H5: ='Model Inputs'!H192 -> 9 | I5: ='Model Inputs'!I192 -> 9 | ... AK5: ='Model Inputs'!AK192 -> 12
A6: Crypto/Web3 Seats | B6: =B5*'Model Inputs'!$B$116 -> 0 | C6: =C5*'Model Inputs'!$B$116 -> 0 | D6: =D5*'Model Inputs'!$B$116 -> 0 | E6: =E5*'Model Inputs'!$B$116 -> 176 | F6: =F5*'Model Inputs'!$B$116 -> 132 | G6: =G5*'Model Inputs'!$B$116 -> 154 | H6: =H5*'Model Inputs'!$B$116 -> 198 | I6: =I5*'Model Inputs'!$B$116 -> 198 | ... M6: =M5*'Model Inputs'!$B$116 -> 198 | N6: =N5*'Model Inputs'!$C$116 -> 175 | O6: =O5*'Model Inputs'!$C$116 -> 175 | P6: =P5*'Model Inputs'!$C$116 -> 175 | Q6: =Q5*'Model Inputs'!$C$116 -> 200 | R6: =R5*'Model Inputs'!$C$116 -> 225 | S6: =S5*'Model Inputs'!$C$116 -> 275 | T6: =T5*'Model Inputs'!$C$116 -> 300 | U6: =U5*'Model Inputs'!$C$116 -> 300 | ... Y6: =Y5*'Model Inputs'!$C$116 -> 375 | Z6: =Z5*'Model Inputs'!$D$116 -> 336 | AA6: =AA5*'Model Inputs'!$D$116 -> 336 | AB6: =AB5*'Model Inputs'!$D$116 -> 336 | AC6: =AC5*'Model Inputs'!$D$116 -> 336 | AD6: =AD5*'Model Inputs'!$D$116 -> 336 | AE6: =AE5*'Model Inputs'!$D$116 -> 336 | AF6: =AF5*'Model Inputs'!$D$116 -> 336 | AG6: =AG5*'Model Inputs'!$D$116 -> 336 | ... AL6: =AL5*'Model Inputs'!$D$116 -> 0
A7: Crypto Law Accounts | B7: ='Model Inputs'!B193 -> 0 | C7: ='Model Inputs'!C193 -> 0 | D7: ='Model Inputs'!D193 -> 0 | E7: ='Model Inputs'!E193 -> 1 | F7: ='Model Inputs'!F193 -> 0 | G7: ='Model Inputs'!G193 -> 1 | H7: ='Model Inputs'!H193 -> 1 | I7: ='Model Inputs'!I193 -> 1 | ... AK7: ='Model Inputs'!AK193 -> 2
A8: Crypto Law Seats | B8: =B7*'Model Inputs'!$B$117 -> 0 | C8: =C7*'Model Inputs'!$B$117 -> 0 | D8: =D7*'Model Inputs'!$B$117 -> 0 | E8: =E7*'Model Inputs'!$B$117 -> 44 | F8: =F7*'Model Inputs'!$B$117 -> 0 | G8: =G7*'Model Inputs'!$B$117 -> 44 | H8: =H7*'Model Inputs'!$B$117 -> 44 | I8: =I7*'Model Inputs'!$B$117 -> 44 | ... M8: =M7*'Model Inputs'!$B$117 -> 44 | N8: =N7*'Model Inputs'!$C$117 -> 50 | O8: =O7*'Model Inputs'!$C$117 -> 50 | P8: =P7*'Model Inputs'!$C$117 -> 50 | Q8: =Q7*'Model Inputs'!$C$117 -> 50 | R8: =R7*'Model Inputs'!$C$117 -> 50 | S8: =S7*'Model Inputs'!$C$117 -> 50 | T8: =T7*'Model Inputs'!$C$117 -> 50 | U8: =U7*'Model Inputs'!$C$117 -> 50 | ... Y8: =Y7*'Model Inputs'!$C$117 -> 100 | Z8: =Z7*'Model Inputs'!$D$117 -> 120 | AA8: =AA7*'Model Inputs'!$D$117 -> 120 | AB8: =AB7*'Model Inputs'!$D$117 -> 120 | AC8: =AC7*'Model Inputs'!$D$117 -> 120 | AD8: =AD7*'Model Inputs'!$D$117 -> 120 | AE8: =AE7*'Model Inputs'!$D$117 -> 120 | AF8: =AF7*'Model Inputs'!$D$117 -> 120 | AG8: =AG7*'Model Inputs'!$D$117 -> 120 | ... AL8: =AL7*'Model Inputs'!$D$117 -> 0
A9: Healthcare Accounts (Y2+) | B9: ='Model Inputs'!B194 -> 0 | C9: ='Model Inputs'!C194 -> 0 | D9: ='Model Inputs'!D194 -> 0 | E9: ='Model Inputs'!E194 -> 0 | F9: ='Model Inputs'!F194 -> 0 | G9: ='Model Inputs'!G194 -> 0 | H9: ='Model Inputs'!H194 -> 0 | I9: ='Model Inputs'!I194 -> 0 | ... AK9: ='Model Inputs'!AK194 -> 2
A10: Healthcare Seats | B10: =B9*'Model Inputs'!$B$118 -> 0 | C10: =C9*'Model Inputs'!$B$118 -> 0 | D10: =D9*'Model Inputs'!$B$118 -> 0 | E10: =E9*'Model Inputs'!$B$118 -> 0 | F10: =F9*'Model Inputs'!$B$118 -> 0 | G10: =G9*'Model Inputs'!$B$118 -> 0 | H10: =H9*'Model Inputs'!$B$118 -> 0 | I10: =I9*'Model Inputs'!$B$118 -> 0 | ... M10: =M9*'Model Inputs'!$B$118 -> 0 | N10: =N9*'Model Inputs'!$C$118 -> 15 | O10: =O9*'Model Inputs'!$C$118 -> 15 | P10: =P9*'Model Inputs'!$C$118 -> 15 | Q10: =Q9*'Model Inputs'!$C$118 -> 15 | R10: =R9*'Model Inputs'!$C$118 -> 15 | S10: =S9*'Model Inputs'!$C$118 -> 30 | T10: =T9*'Model Inputs'!$C$118 -> 30 | U10: =U9*'Model Inputs'!$C$118 -> 30 | ... Y10: =Y9*'Model Inputs'!$C$118 -> 30 | Z10: =Z9*'Model Inputs'!$D$118 -> 40 | AA10: =AA9*'Model Inputs'!$D$118 -> 40 | AB10: =AB9*'Model Inputs'!$D$118 -> 40 | AC10: =AC9*'Model Inputs'!$D$118 -> 40 | AD10: =AD9*'Model Inputs'!$D$118 -> 40 | AE10: =AE9*'Model Inputs'!$D$118 -> 40 | AF10: =AF9*'Model Inputs'!$D$118 -> 40 | AG10: =AG9*'Model Inputs'!$D$118 -> 40 | ... AL10: =AL9*'Model Inputs'!$D$118 -> 0
A11: Family Office Accounts (Y2+) | B11: ='Model Inputs'!B195 -> 0 | C11: ='Model Inputs'!C195 -> 0 | D11: ='Model Inputs'!D195 -> 0 | E11: ='Model Inputs'!E195 -> 0 | F11: ='Model Inputs'!F195 -> 0 | G11: ='Model Inputs'!G195 -> 0 | H11: ='Model Inputs'!H195 -> 0 | I11: ='Model Inputs'!I195 -> 0 | ... AK11: ='Model Inputs'!AK195 -> 2
A12: Family Office Seats | B12: =B11*'Model Inputs'!$B$119 -> 0 | C12: =C11*'Model Inputs'!$B$119 -> 0 | D12: =D11*'Model Inputs'!$B$119 -> 0 | E12: =E11*'Model Inputs'!$B$119 -> 0 | F12: =F11*'Model Inputs'!$B$119 -> 0 | G12: =G11*'Model Inputs'!$B$119 -> 0 | H12: =H11*'Model Inputs'!$B$119 -> 0 | I12: =I11*'Model Inputs'!$B$119 -> 0 | ... M12: =M11*'Model Inputs'!$B$119 -> 0 | N12: =N11*'Model Inputs'!$C$119 -> 0 | O12: =O11*'Model Inputs'!$C$119 -> 0 | P12: =P11*'Model Inputs'!$C$119 -> 0 | Q12: =Q11*'Model Inputs'!$C$119 -> 10 | R12: =R11*'Model Inputs'!$C$119 -> 10 | S12: =S11*'Model Inputs'!$C$119 -> 10 | T12: =T11*'Model Inputs'!$C$119 -> 10 | U12: =U11*'Model Inputs'!$C$119 -> 10 | ... Y12: =Y11*'Model Inputs'!$C$119 -> 10 | Z12: =Z11*'Model Inputs'!$D$119 -> 28 | AA12: =AA11*'Model Inputs'!$D$119 -> 28 | AB12: =AB11*'Model Inputs'!$D$119 -> 28 | AC12: =AC11*'Model Inputs'!$D$119 -> 28 | AD12: =AD11*'Model Inputs'!$D$119 -> 28 | AE12: =AE11*'Model Inputs'!$D$119 -> 28 | AF12: =AF11*'Model Inputs'!$D$119 -> 28 | AG12: =AG11*'Model Inputs'!$D$119 -> 28 | ... AL12: =AL11*'Model Inputs'!$D$119 -> 0
A13: General Legal Accounts (Y2+) | B13: ='Model Inputs'!B196 -> 0 | C13: ='Model Inputs'!C196 -> 0 | D13: ='Model Inputs'!D196 -> 0 | E13: ='Model Inputs'!E196 -> 0 | F13: ='Model Inputs'!F196 -> 0 | G13: ='Model Inputs'!G196 -> 0 | H13: ='Model Inputs'!H196 -> 0 | I13: ='Model Inputs'!I196 -> 0 | ... AK13: ='Model Inputs'!AK196 -> 2
A14: General Legal Seats | B14: =B13*'Model Inputs'!$B$120 -> 0 | C14: =C13*'Model Inputs'!$B$120 -> 0 | D14: =D13*'Model Inputs'!$B$120 -> 0 | E14: =E13*'Model Inputs'!$B$120 -> 0 | F14: =F13*'Model Inputs'!$B$120 -> 0 | G14: =G13*'Model Inputs'!$B$120 -> 0 | H14: =H13*'Model Inputs'!$B$120 -> 0 | I14: =I13*'Model Inputs'!$B$120 -> 0 | ... M14: =M13*'Model Inputs'!$B$120 -> 0 | N14: =N13*'Model Inputs'!$C$120 -> 35 | O14: =O13*'Model Inputs'!$C$120 -> 35 | P14: =P13*'Model Inputs'!$C$120 -> 35 | Q14: =Q13*'Model Inputs'!$C$120 -> 35 | R14: =R13*'Model Inputs'!$C$120 -> 35 | S14: =S13*'Model Inputs'!$C$120 -> 35 | T14: =T13*'Model Inputs'!$C$120 -> 35 | U14: =U13*'Model Inputs'!$C$120 -> 35 | ... Y14: =Y13*'Model Inputs'!$C$120 -> 70 | Z14: =Z13*'Model Inputs'!$D$120 -> 90 | AA14: =AA13*'Model Inputs'!$D$120 -> 90 | AB14: =AB13*'Model Inputs'!$D$120 -> 90 | AC14: =AC13*'Model Inputs'!$D$120 -> 90 | AD14: =AD13*'Model Inputs'!$D$120 -> 90 | AE14: =AE13*'Model Inputs'!$D$120 -> 90 | AF14: =AF13*'Model Inputs'!$D$120 -> 90 | AG14: =AG13*'Model Inputs'!$D$120 -> 90 | ... AL14: =AL13*'Model Inputs'!$D$120 -> 0
A15: Total Sales Accounts | B15: =B5+B7+B9+B11+B13+B18 -> 0 | C15: =C5+C7+C9+C11+C13+C18 -> 0 | D15: =D5+D7+D9+D11+D13+D18 -> 0 | E15: =E5+E7+E9+E11+E13+E18 -> 9 | F15: =F5+F7+F9+F11+F13+F18 -> 6 | G15: =G5+G7+G9+G11+G13+G18 -> 8 | H15: =H5+H7+H9+H11+H13+H18 -> 10 | I15: =I5+I7+I9+I11+I13+I18 -> 10 | ... AK15: =AK5+AK7+AK9+AK11+AK13+AK18 -> 27 | AL15: =AL5+AL7+AL9+AL11+AL13 -> 0
A16: Total Sales Seats | B16: =B6+B8+B10+B12+B14 -> 0 | C16: =C6+C8+C10+C12+C14 -> 0 | D16: =D6+D8+D10+D12+D14 -> 0 | E16: =E6+E8+E10+E12+E14 -> 220 | F16: =F6+F8+F10+F12+F14 -> 132 | G16: =G6+G8+G10+G12+G14 -> 198 | H16: =H6+H8+H10+H12+H14 -> 242 | I16: =I6+I8+I10+I12+I14 -> 242 | ... AL16: =AL6+AL8+AL10+AL12+AL14 -> 0
A17: Enterprise/MM Seats (Y2+) | B17: 0 | C17: 0 | D17: 0 | E17: 0 | F17: 0 | G17: 0 | H17: 0 | I17: 0 | J17: 0 | K17: 0 | L17: 0 | M17: 0 | N17: ='Model Inputs'!B148 -> 0 | O17: ='Model Inputs'!C148 -> 0 | P17: ='Model Inputs'!D148 -> 50 | Q17: ='Model Inputs'!E148 -> 50 | R17: ='Model Inputs'!F148 -> 50 | S17: ='Model Inputs'!G148 -> 100 | T17: ='Model Inputs'!H148 -> 100 | U17: ='Model Inputs'!I148 -> 100 | ... Y17: ='Model Inputs'!M148 -> 150 | Z17: ='Model Inputs'!B$145 -> 125 | AA17: ='Model Inputs'!C$145 -> 125 | AB17: ='Model Inputs'!D$145 -> 125 | AC17: ='Model Inputs'!E$145 -> 250 | AD17: ='Model Inputs'!F$145 -> 250 | AE17: ='Model Inputs'!G$145 -> 250 | AF17: ='Model Inputs'!H$145 -> 425 | AG17: ='Model Inputs'!I$145 -> 425 | ... AK17: ='Model Inputs'!M$145 -> 550
A18: Enterprise/MM Accounts (Y2+) | B18: 0 | C18: 0 | D18: 0 | E18: 0 | F18: 0 | G18: 0 | H18: 0 | I18: 0 | J18: 0 | K18: 0 | L18: 0 | M18: 0 | N18: ='Model Inputs'!B147 -> 0 | O18: ='Model Inputs'!C147 -> 0 | P18: ='Model Inputs'!D147 -> 1 | Q18: ='Model Inputs'!E147 -> 1 | R18: ='Model Inputs'!F147 -> 1 | S18: ='Model Inputs'!G147 -> 2 | T18: ='Model Inputs'!H147 -> 2 | U18: ='Model Inputs'!I147 -> 2 | ... Y18: ='Model Inputs'!M147 -> 3 | Z18: ='Model Inputs'!B144 -> 2 | AA18: ='Model Inputs'!C144 -> 2 | AB18: ='Model Inputs'!D144 -> 2 | AC18: ='Model Inputs'!E144 -> 4 | AD18: ='Model Inputs'!F144 -> 4 | AE18: ='Model Inputs'!G144 -> 4 | AF18: ='Model Inputs'!H144 -> 6 | AG18: ='Model Inputs'!I144 -> 6 | ... AK18: ='Model Inputs'!M144 -> 7
A19: PLG Accounts | B19: ='Model Inputs'!B20 -> 0 | C19: ='Model Inputs'!C20 -> 0 | D19: ='Model Inputs'!D20 -> 0 | E19: ='Model Inputs'!E20 -> 22 | F19: ='Model Inputs'!F20 -> 12 | G19: ='Model Inputs'!G20 -> 17 | H19: ='Model Inputs'!H20 -> 19 | I19: ='Model Inputs'!I20 -> 18 | ... AL19: ='Model Inputs'!AL20 -> 0
A20: PLG Seats | B20: ='Model Inputs'!B19 -> 0 | C20: ='Model Inputs'!C19 -> 0 | D20: ='Model Inputs'!D19 -> 0 | E20: ='Model Inputs'!E19 -> 22 | F20: ='Model Inputs'!F19 -> 13 | G20: ='Model Inputs'!G19 -> 20 | H20: ='Model Inputs'!H19 -> 24 | I20: ='Model Inputs'!I19 -> 24 | ... AL20: ='Model Inputs'!AL19 -> 0
A21: REFERRALS
A22: Referral Accounts | B22: 0 | C22: =ROUND(B35*'Model Inputs'!C41,0) -> 0 | D22: =ROUND(C35*'Model Inputs'!D41,0) -> 0 | E22: =ROUND(D35*'Model Inputs'!E41,0) -> 0 | F22: =ROUND(E35*'Model Inputs'!F41,0) -> 0 | G22: =ROUND(F35*'Model Inputs'!G41,0) -> 0 | H22: =ROUND(G35*'Model Inputs'!H41,0) -> 0 | I22: =ROUND(H35*'Model Inputs'!I41,0) -> 0 | J22: =ROUND(I35*'Model Inputs'!J41,0) -> 1 | ... AL22: =ROUND(AK35*'Model Inputs'!AL41,0) -> 11 | AM22: =ROUND(AL35*'Model Inputs'!$B$41,0) -> 5 | AN22: =ROUND(AM35*'Model Inputs'!$B$41,0) -> 0
A23: Referral Seats | B23: =B22*IF(1<=12,'Model Inputs'!$B$122,IF(1<=24,'Model Inputs'!$C$122,'Model Inputs'!$D$122)) -> 0 | C23: =C22*IF(2<=12,'Model Inputs'!$B$122,IF(2<=24,'Model Inputs'!$C$122,'Model Inputs'!$D$122)) -> 0 | D23: =D22*IF(3<=12,'Model Inputs'!$B$122,IF(3<=24,'Model Inputs'!$C$122,'Model Inputs'!$D$122)) -> 0 | E23: =E22*IF(4<=12,'Model Inputs'!$B$122,IF(4<=24,'Model Inputs'!$C$122,'Model Inputs'!$D$122)) -> 0 | F23: =F22*IF(5<=12,'Model Inputs'!$B$122,IF(5<=24,'Model Inputs'!$C$122,'Model Inputs'!$D$122)) -> 0 | G23: =G22*IF(6<=12,'Model Inputs'!$B$122,IF(6<=24,'Model Inputs'!$C$122,'Model Inputs'!$D$122)) -> 0 | H23: =H22*IF(7<=12,'Model Inputs'!$B$122,IF(7<=24,'Model Inputs'!$C$122,'Model Inputs'!$D$122)) -> 0 | I23: =I22*IF(8<=12,'Model Inputs'!$B$122,IF(8<=24,'Model Inputs'!$C$122,'Model Inputs'!$D$122)) -> 0 | J23: =J22*IF(9<=12,'Model Inputs'!$B$122,IF(9<=24,'Model Inputs'!$C$122,'Model Inputs'!$D$122)) -> 20 | K23: =K22*IF(10<=12,'Model Inputs'!$B$122,IF(10<=24,'Model Inputs'!$C$122,'Model Inputs'!$D$122)) -> 20 | L23: =L22*IF(11<=12,'Model Inputs'!$B$122,IF(11<=24,'Model Inputs'!$C$122,'Model Inputs'!$D$122)) -> 20 | M23: =M22*IF(12<=12,'Model Inputs'!$B$122,IF(12<=24,'Model Inputs'!$C$122,'Model Inputs'!$D$122)) -> 20 | N23: =N22*IF(13<=12,'Model Inputs'!$B$122,IF(13<=24,'Model Inputs'!$C$122,'Model Inputs'!$D$122)) -> 25 | O23: =O22*IF(14<=12,'Model Inputs'!$B$122,IF(14<=24,'Model Inputs'!$C$122,'Model Inputs'!$D$122)) -> 50 | P23: =P22*IF(15<=12,'Model Inputs'!$B$122,IF(15<=24,'Model Inputs'!$C$122,'Model Inputs'!$D$122)) -> 50 | Q23: =Q22*IF(16<=12,'Model Inputs'!$B$122,IF(16<=24,'Model Inputs'!$C$122,'Model Inputs'!$D$122)) -> 50 | R23: =R22*IF(17<=12,'Model Inputs'!$B$122,IF(17<=24,'Model Inputs'!$C$122,'Model Inputs'!$D$122)) -> 50 | S23: =S22*IF(18<=12,'Model Inputs'!$B$122,IF(18<=24,'Model Inputs'!$C$122,'Model Inputs'!$D$122)) -> 50 | T23: =T22*IF(19<=12,'Model Inputs'!$B$122,IF(19<=24,'Model Inputs'!$C$122,'Model Inputs'!$D$122)) -> 75 | U23: =U22*IF(20<=12,'Model Inputs'!$B$122,IF(20<=24,'Model Inputs'!$C$122,'Model Inputs'!$D$122)) -> 75 | V23: =V22*IF(21<=12,'Model Inputs'!$B$122,IF(21<=24,'Model Inputs'!$C$122,'Model Inputs'!$D$122)) -> 75 | W23: =W22*IF(22<=12,'Model Inputs'!$B$122,IF(22<=24,'Model Inputs'!$C$122,'Model Inputs'!$D$122)) -> 75 | X23: =X22*IF(23<=12,'Model Inputs'!$B$122,IF(23<=24,'Model Inputs'!$C$122,'Model Inputs'!$D$122)) -> 100 | Y23: =Y22*IF(24<=12,'Model Inputs'!$B$122,IF(24<=24,'Model Inputs'!$C$122,'Model Inputs'!$D$122)) -> 100 | Z23: =Z22*IF(25<=12,'Model Inputs'!$B$122,IF(25<=24,'Model Inputs'!$C$122,'Model Inputs'!$D$122)) -> 168 | AA23: =AA22*IF(26<=12,'Model Inputs'!$B$122,IF(26<=24,'Model Inputs'!$C$122,'Model Inputs'!$D$122)) -> 168 | AB23: =AB22*IF(27<=12,'Model Inputs'!$B$122,IF(27<=24,'Model Inputs'!$C$122,'Model Inputs'!$D$122)) -> 168 | AC23: =AC22*IF(28<=12,'Model Inputs'!$B$122,IF(28<=24,'Model Inputs'!$C$122,'Model Inputs'!$D$122)) -> 196 | AD23: =AD22*IF(29<=12,'Model Inputs'!$B$122,IF(29<=24,'Model Inputs'!$C$122,'Model Inputs'!$D$122)) -> 196 | AE23: =AE22*IF(30<=12,'Model Inputs'!$B$122,IF(30<=24,'Model Inputs'!$C$122,'Model Inputs'!$D$122)) -> 224 | AF23: =AF22*IF(31<=12,'Model Inputs'!$B$122,IF(31<=24,'Model Inputs'!$C$122,'Model Inputs'!$D$122)) -> 224 | AG23: =AG22*IF(32<=12,'Model Inputs'!$B$122,IF(32<=24,'Model Inputs'!$C$122,'Model Inputs'!$D$122)) -> 224 | AH23: =AH22*IF(33<=12,'Model Inputs'!$B$122,IF(33<=24,'Model Inputs'!$C$122,'Model Inputs'!$D$122)) -> 252 | AI23: =AI22*IF(34<=12,'Model Inputs'!$B$122,IF(34<=24,'Model Inputs'!$C$122,'Model Inputs'!$D$122)) -> 252 | AJ23: =AJ22*IF(35<=12,'Model Inputs'!$B$122,IF(35<=24,'Model Inputs'!$C$122,'Model Inputs'!$D$122)) -> 280 | AK23: =AK22*IF(36<=12,'Model Inputs'!$B$122,IF(36<=24,'Model Inputs'!$C$122,'Model Inputs'!$D$122)) -> 280 | AL23: =AL22*IF(37<=12,'Model Inputs'!$B$122,IF(37<=24,'Model Inputs'!$C$122,'Model Inputs'!$D$122)) -> 308 | AM23: =AM22*IF(38<=12,'Model Inputs'!$B$122,IF(38<=24,'Model Inputs'!$C$122,'Model Inputs'!$D$122)) -> 140 | AN23: =AN22*IF(39<=12,'Model Inputs'!$B$122,IF(39<=24,'Model Inputs'!$C$122,'Model Inputs'!$D$122)) -> 0
A24: SEAT METRICS
A25: Previous Active Seats | B25: 0 | C25: =B28 -> 0 | D25: =C28 -> 0 | E25: =D28 -> 0 | F25: =E28 -> 242 | G25: =F28 -> 386 | H25: =G28 -> 602 | I25: =H28 -> 866 | J25: =I28 -> 1129 | ... AL25: =AK28 -> 23091
A26: Churned Seats | B26: =ROUND(B25*'Model Inputs'!$E$41,0) -> 0 | C26: =ROUND(C25*'Model Inputs'!$E$41,0) -> 0 | D26: =ROUND(D25*'Model Inputs'!$E$41,0) -> 0 | E26: =ROUND(E25*'Model Inputs'!$E$41,0) -> 0 | F26: =ROUND(F25*'Model Inputs'!$E$41,0) -> 1 | G26: =ROUND(G25*'Model Inputs'!$E$41,0) -> 2 | H26: =ROUND(H25*'Model Inputs'!$E$41,0) -> 2 | I26: =ROUND(I25*'Model Inputs'!$E$41,0) -> 3 | ... AN26: =ROUND(AN25*'Model Inputs'!$E$41,0) -> 0
A27: New Seats (Total) | B27: =B16+B17+B20+B23 -> 0 | C27: =C16+C17+C20+C23 -> 0 | D27: =D16+D17+D20+D23 -> 0 | E27: =E16+E17+E20+E23 -> 242 | F27: =F16+F17+F20+F23 -> 145 | G27: =G16+G17+G20+G23 -> 218 | H27: =H16+H17+H20+H23 -> 266 | I27: =I16+I17+I20+I23 -> 266 | ... AL27: =AL16+AL17+AL20+AL23 -> 308
A28: Active Seats (EOP) | B28: =B25-B26+B27 -> 0 | C28: =C25-C26+C27 -> 0 | D28: =D25-D26+D27 -> 0 | E28: =E25-E26+E27 -> 242 | F28: =F25-F26+F27 -> 386 | G28: =G25-G26+G27 -> 602 | H28: =H25-H26+H27 -> 866 | I28: =I25-I26+I27 -> 1129 | ... AL28: =AL25-AL26+AL27 -> 23307
A29: REVENUE
A30: Blended Effective Rate | B30: =IF(B16+B20+B23>0,(B6*'Model Inputs'!$B$7+B8*'Model Inputs'!$B$8+B10*'Model Inputs'!$B$8+B12*'Model Inputs'!$B$7+B14*'Model Inputs'!$B$8+B20*15+B23*'Model Inputs'!$B$7)/(B16+B20+B23),0) -> 0 | C30: =IF(C16+C20+C23>0,(C6*'Model Inputs'!$B$7+C8*'Model Inputs'!$B$8+C10*'Model Inputs'!$B$8+C12*'Model Inputs'!$B$7+C14*'Model Inputs'!$B$8+C20*15+C23*'Model Inputs'!$B$7)/(C16+C20+C23),0) -> 0 | D30: =IF(D16+D20+D23>0,(D6*'Model Inputs'!$B$7+D8*'Model Inputs'!$B$8+D10*'Model Inputs'!$B$8+D12*'Model Inputs'!$B$7+D14*'Model Inputs'!$B$8+D20*15+D23*'Model Inputs'!$B$7)/(D16+D20+D23),0) -> 0 | E30: =IF(E16+E20+E23>0,(E6*'Model Inputs'!$B$7+E8*'Model Inputs'!$B$8+E10*'Model Inputs'!$B$8+E12*'Model Inputs'!$B$7+E14*'Model Inputs'!$B$8+E20*15+E23*'Model Inputs'!$B$7)/(E16+E20+E23),0) -> 29.545455 | F30: =IF(F16+F20+F23>0,(F6*'Model Inputs'!$B$7+F8*'Model Inputs'!$B$8+F10*'Model Inputs'!$B$8+F12*'Model Inputs'!$B$7+F14*'Model Inputs'!$B$8+F20*15+F23*'Model Inputs'!$B$7)/(F16+F20+F23),0) -> 27.744828 | G30: =IF(G16+G20+G23>0,(G6*'Model Inputs'!$B$7+G8*'Model Inputs'!$B$8+G10*'Model Inputs'!$B$8+G12*'Model Inputs'!$B$7+G14*'Model Inputs'!$B$8+G20*15+G23*'Model Inputs'!$B$7)/(G16+G20+G23),0) -> 29.733945 | H30: =IF(H16+H20+H23>0,(H6*'Model Inputs'!$B$7+H8*'Model Inputs'!$B$8+H10*'Model Inputs'!$B$8+H12*'Model Inputs'!$B$7+H14*'Model Inputs'!$B$8+H20*15+H23*'Model Inputs'!$B$7)/(H16+H20+H23),0) -> 29.390977 | I30: =IF(I16+I20+I23>0,(I6*'Model Inputs'!$B$7+I8*'Model Inputs'!$B$8+I10*'Model Inputs'!$B$8+I12*'Model Inputs'!$B$7+I14*'Model Inputs'!$B$8+I20*15+I23*'Model Inputs'!$B$7)/(I16+I20+I23),0) -> 29.390977 | ... AL30: =IF(AL16+AL20+AL23>0,(AL6*'Model Inputs'!$B$7+AL8*'Model Inputs'!$B$8+AL10*'Model Inputs'!$B$8+AL12*'Model Inputs'!$B$7+AL14*'Model Inputs'!$B$8+AL20*15+AL23*'Model Inputs'!$B$7)/(AL16+AL20+AL23),0) -> 29
A31: MRR | B31: =B28*B30 -> 0 | C31: =C28*C30 -> 0 | D31: =D28*D30 -> 0 | E31: =E28*E30 -> 7150 | F31: =F28*F30 -> 10709.503 | G31: =G28*G30 -> 17899.835 | H31: =H28*H30 -> 25452.586 | I31: =I28*I30 -> 33182.414 | ... Y31: =Y28*Y30 -> 275874.33 | Z31: =(Z28-Z17)*Z30+'Model Inputs'!B$146 -> 309107.62 | AA31: =(AA28-AA17)*AA30+'Model Inputs'!C$146 -> 337831.58 | AB31: =(AB28-AB17)*AB30+'Model Inputs'!D$146 -> 366431.74 | AC31: =(AC28-AC17)*AC30+'Model Inputs'!E$146 -> 399887.94 | AD31: =(AD28-AD17)*AD30+'Model Inputs'!F$146 -> 432909.12 | AE31: =(AE28-AE17)*AE30+'Model Inputs'!G$146 -> 465801.02 | AF31: =(AF28-AF17)*AF30+'Model Inputs'!H$146 -> 507450.89 | AG31: =(AG28-AG17)*AG30+'Model Inputs'!I$146 -> 546267.02 | ... AL31: =(AL28-AL17)*AL30+'Model Inputs'!N$146 -> 675903
A32: ARR (MRR × 12) | B32: =B31*12 -> 0 | C32: =C31*12 -> 0 | D32: =D31*12 -> 0 | E32: =E31*12 -> 85800 | F32: =F31*12 -> 128514.04 | G32: =G31*12 -> 214798.02 | H32: =H31*12 -> 305431.04 | I32: =I31*12 -> 398188.96 | ... AL32: =AL31*12 -> 8110836
A33: ACCOUNT METRICS
A34: Total New Accounts | B34: =B15+B19+B22 -> 0 | C34: =C15+C19+C22 -> 0 | D34: =D15+D19+D22 -> 0 | E34: =E15+E19+E22 -> 31 | F34: =F15+F19+F22 -> 18 | G34: =G15+G19+G22 -> 25 | H34: =H15+H19+H22 -> 29 | I34: =I15+I19+I22 -> 28 | ... AL34: =AL15+AL19+AL22 -> 11
A35: Cumulative Accounts | B35: =B34 -> 0 | C35: =B35+C34 -> 0 | D35: =C35+D34 -> 0 | E35: =D35+E34 -> 31 | F35: =E35+F34 -> 49 | G35: =F35+G34 -> 74 | H35: =G35+H34 -> 103 | I35: =H35+I34 -> 131 | J35: =I35+J34 -> 159 | ... AL35: =AK35+AL34 -> 1328
A36: Avg Seats/Account | B36: =IF(B35>0,B28/B35,0) -> 0 | C36: =IF(C35>0,C28/C35,0) -> 0 | D36: =IF(D35>0,D28/D35,0) -> 0 | E36: =IF(E35>0,E28/E35,0) -> 7.8064516 | F36: =IF(F35>0,F28/F35,0) -> 7.877551 | G36: =IF(G35>0,G28/G35,0) -> 8.1351351 | H36: =IF(H35>0,H28/H35,0) -> 8.407767 | I36: =IF(I35>0,I28/I35,0) -> 8.6183206 | ... AL36: =IF(AL35>0,AL28/AL35,0) -> 17.550452
A37: Sales MRR (excl. PLG/Referrals) | E37: =E6*'Model Inputs'!$B$7+E8*'Model Inputs'!$B$8+E10*'Model Inputs'!$B$8+E12*'Model Inputs'!$B$7+E14*'Model Inputs'!$B$8 -> 6820 | F37: =F6*'Model Inputs'!$B$7+F8*'Model Inputs'!$B$8+F10*'Model Inputs'!$B$8+F12*'Model Inputs'!$B$7+F14*'Model Inputs'!$B$8 -> 3828 | G37: =G6*'Model Inputs'!$B$7+G8*'Model Inputs'!$B$8+G10*'Model Inputs'!$B$8+G12*'Model Inputs'!$B$7+G14*'Model Inputs'!$B$8 -> 6182 | H37: =H6*'Model Inputs'!$B$7+H8*'Model Inputs'!$B$8+H10*'Model Inputs'!$B$8+H12*'Model Inputs'!$B$7+H14*'Model Inputs'!$B$8 -> 7458 | I37: =I6*'Model Inputs'!$B$7+I8*'Model Inputs'!$B$8+I10*'Model Inputs'!$B$8+I12*'Model Inputs'!$B$7+I14*'Model Inputs'!$B$8 -> 7458 | J37: =J6*'Model Inputs'!$B$7+J8*'Model Inputs'!$B$8+J10*'Model Inputs'!$B$8+J12*'Model Inputs'!$B$7+J14*'Model Inputs'!$B$8 -> 7458 | K37: =K6*'Model Inputs'!$B$7+K8*'Model Inputs'!$B$8+K10*'Model Inputs'!$B$8+K12*'Model Inputs'!$B$7+K14*'Model Inputs'!$B$8 -> 7458 | L37: =L6*'Model Inputs'!$B$7+L8*'Model Inputs'!$B$8+L10*'Model Inputs'!$B$8+L12*'Model Inputs'!$B$7+L14*'Model Inputs'!$B$8 -> 7458 | ... AN37: =AN6*'Model Inputs'!$B$7+AN8*'Model Inputs'!$B$8+AN10*'Model Inputs'!$B$8+AN12*'Model Inputs'!$B$7+AN14*'Model Inputs'!$B$8 -> 0
A40: BOTTOM-UP MODEL ASSUMPTIONS & METHODOLOGY
A42: 1. SALES CAPACITY LOGIC
A43: Parameter | B43: Value | C43: Rationale
A44: Founder Capacity | B44: 5 deals/mo | C44: ~50% sales focus (balance: product, fundraising, ops)
...

Sheet COGS Analysis
A1: COGS ANALYSIS - 36-MONTH DETAIL
A3: Component | B3: Y1M1 | C3: Y1M2 | D3: Y1M3 | E3: Y1M4 | F3: Y1M5 | G3: Y1M6 | H3: Y1M7 | I3: Y1M8 | J3: Y1M9 | K3: Y1M10 | L3: Y1M11 | M3: Y1M12 | N3: Y2M1 | O3: Y2M2 | P3: Y2M3 | Q3: Y2M4 | R3: Y2M5 | S3: Y2M6 | T3: Y2M7 | U3: Y2M8 | V3: Y2M9 | W3: Y2M10 | X3: Y2M11 | Y3: Y2M12 | Z3: Y3M1 | AA3: Y3M2 | AB3: Y3M3 | AC3: Y3M4 | AD3: Y3M5 | AE3: Y3M6 | AF3: Y3M7 | AG3: Y3M8 | AH3: Y3M9 | AI3: Y3M10 | AJ3: Y3M11 | AK3: Y3M12
A4: VARIABLE COSTS (Scale with seats)
A5: Storage | B5: ='Revenue Model'!B$28*'Model Inputs'!$B$60 -> 0 | C5: ='Revenue Model'!C$28*'Model Inputs'!$B$60 -> 0 | D5: ='Revenue Model'!D$28*'Model Inputs'!$B$60 -> 0 | E5: ='Revenue Model'!E$28*'Model Inputs'!$B$60 -> 822.8 | F5: ='Revenue Model'!F$28*'Model Inputs'!$B$60 -> 1312.4 | G5: ='Revenue Model'!G$28*'Model Inputs'!$B$60 -> 2046.8 | H5: ='Revenue Model'!H$28*'Model Inputs'!$B$60 -> 2944.4 | I5: ='Revenue Model'!I$28*'Model Inputs'!$B$60 -> 3838.6 | ... M5: ='Revenue Model'!M$28*'Model Inputs'!$B$60 -> 7639.8 | N5: ='Revenue Model'!N$28*'Model Inputs'!$C$60 -> 6928.2 | O5: ='Revenue Model'!O$28*'Model Inputs'!$C$60 -> 7854.3 | P5: ='Revenue Model'!P$28*'Model Inputs'!$C$60 -> 8910 | Q5: ='Revenue Model'!Q$28*'Model Inputs'!$C$60 -> 10065.6 | R5: ='Revenue Model'!R$28*'Model Inputs'!$C$60 -> 11291.4 | S5: ='Revenue Model'!S$28*'Model Inputs'!$C$60 -> 12838.5 | T5: ='Revenue Model'!T$28*'Model Inputs'!$C$60 -> 14523.3 | U5: ='Revenue Model'!U$28*'Model Inputs'!$C$60 -> 16200 | ... Y5: ='Revenue Model'!Y$28*'Model Inputs'!$C$60 -> 24359.4 | Z5: ='Revenue Model'!Z$28*'Model Inputs'!$D$60 -> 20704.32 | AA5: ='Revenue Model'!AA$28*'Model Inputs'!$D$60 -> 22634.56 | AB5: ='Revenue Model'!AB$28*'Model Inputs'!$D$60 -> 24556.48 | AC5: ='Revenue Model'!AC$28*'Model Inputs'!$D$60 -> 26790.4 | AD5: ='Revenue Model'!AD$28*'Model Inputs'!$D$60 -> 29013.92 | AE5: ='Revenue Model'!AE$28*'Model Inputs'!$D$60 -> 31287.36 | AF5: ='Revenue Model'!AF$28*'Model Inputs'!$D$60 -> 33916.48 | AG5: ='Revenue Model'!AG$28*'Model Inputs'!$D$60 -> 36535.2 | ... AL5: ='Revenue Model'!AL$28*'Model Inputs'!$D$60 -> 48478.56
A6: Bandwidth | B6: ='Revenue Model'!B$28*'Model Inputs'!$B$61 -> 0 | C6: ='Revenue Model'!C$28*'Model Inputs'!$B$61 -> 0 | D6: ='Revenue Model'!D$28*'Model Inputs'!$B$61 -> 0 | E6: ='Revenue Model'!E$28*'Model Inputs'!$B$61 -> 174.24 | F6: ='Revenue Model'!F$28*'Model Inputs'!$B$61 -> 277.92 | G6: ='Revenue Model'!G$28*'Model Inputs'!$B$61 -> 433.44 | H6: ='Revenue Model'!H$28*'Model Inputs'!$B$61 -> 623.52 | I6: ='Revenue Model'!I$28*'Model Inputs'!$B$61 -> 812.88 | ... M6: ='Revenue Model'!M$28*'Model Inputs'!$B$61 -> 1617.84 | N6: ='Revenue Model'!N$28*'Model Inputs'!$C$61 -> 1206.02 | O6: ='Revenue Model'!O$28*'Model Inputs'!$C$61 -> 1367.23 | P6: ='Revenue Model'!P$28*'Model Inputs'!$C$61 -> 1551 | Q6: ='Revenue Model'!Q$28*'Model Inputs'!$C$61 -> 1752.16 | R6: ='Revenue Model'!R$28*'Model Inputs'!$C$61 -> 1965.54 | S6: ='Revenue Model'!S$28*'Model Inputs'!$C$61 -> 2234.85 | T6: ='Revenue Model'!T$28*'Model Inputs'!$C$61 -> 2528.13 | U6: ='Revenue Model'!U$28*'Model Inputs'!$C$61 -> 2820 | ... Y6: ='Revenue Model'!Y$28*'Model Inputs'!$C$61 -> 4240.34 | Z6: ='Revenue Model'!Z$28*'Model Inputs'!$D$61 -> 3085.74 | AA6: ='Revenue Model'!AA$28*'Model Inputs'!$D$61 -> 3373.42 | AB6: ='Revenue Model'!AB$28*'Model Inputs'!$D$61 -> 3659.86 | AC6: ='Revenue Model'!AC$28*'Model Inputs'!$D$61 -> 3992.8 | AD6: ='Revenue Model'!AD$28*'Model Inputs'!$D$61 -> 4324.19 | AE6: ='Revenue Model'!AE$28*'Model Inputs'!$D$61 -> 4663.02 | AF6: ='Revenue Model'!AF$28*'Model Inputs'!$D$61 -> 5054.86 | AG6: ='Revenue Model'!AG$28*'Model Inputs'!$D$61 -> 5445.15 | ... AL6: ='Revenue Model'!AL$28*'Model Inputs'!$D$61 -> 7225.17
A7: Compute | B7: ='Revenue Model'!B$28*'Model Inputs'!$B$62 -> 0 | C7: ='Revenue Model'!C$28*'Model Inputs'!$B$62 -> 0 | D7: ='Revenue Model'!D$28*'Model Inputs'!$B$62 -> 0 | E7: ='Revenue Model'!E$28*'Model Inputs'!$B$62 -> 29.04 | F7: ='Revenue Model'!F$28*'Model Inputs'!$B$62 -> 46.32 | G7: ='Revenue Model'!G$28*'Model Inputs'!$B$62 -> 72.24 | H7: ='Revenue Model'!H$28*'Model Inputs'!$B$62 -> 103.92 | I7: ='Revenue Model'!I$28*'Model Inputs'!$B$62 -> 135.48 | ... M7: ='Revenue Model'!M$28*'Model Inputs'!$B$62 -> 269.64 | N7: ='Revenue Model'!N$28*'Model Inputs'!$C$62 -> 205.28 | O7: ='Revenue Model'!O$28*'Model Inputs'!$C$62 -> 232.72 | P7: ='Revenue Model'!P$28*'Model Inputs'!$C$62 -> 264 | Q7: ='Revenue Model'!Q$28*'Model Inputs'!$C$62 -> 298.24 | R7: ='Revenue Model'!R$28*'Model Inputs'!$C$62 -> 334.56 | S7: ='Revenue Model'!S$28*'Model Inputs'!$C$62 -> 380.4 | T7: ='Revenue Model'!T$28*'Model Inputs'!$C$62 -> 430.32 | U7: ='Revenue Model'!U$28*'Model Inputs'!$C$62 -> 480 | ... Y7: ='Revenue Model'!Y$28*'Model Inputs'!$C$62 -> 721.76 | Z7: ='Revenue Model'!Z$28*'Model Inputs'!$D$62 -> 597.24 | AA7: ='Revenue Model'!AA$28*'Model Inputs'!$D$62 -> 652.92 | AB7: ='Revenue Model'!AB$28*'Model Inputs'!$D$62 -> 708.36 | AC7: ='Revenue Model'!AC$28*'Model Inputs'!$D$62 -> 772.8 | AD7: ='Revenue Model'!AD$28*'Model Inputs'!$D$62 -> 836.94 | AE7: ='Revenue Model'!AE$28*'Model Inputs'!$D$62 -> 902.52 | AF7: ='Revenue Model'!AF$28*'Model Inputs'!$D$62 -> 978.36 | AG7: ='Revenue Model'!AG$28*'Model Inputs'!$D$62 -> 1053.9 | ... AL7: ='Revenue Model'!AL$28*'Model Inputs'!$D$62 -> 1398.42
A8: Data Replication | B8: ='Revenue Model'!B$28*'Model Inputs'!$B$63 -> 0 | C8: ='Revenue Model'!C$28*'Model Inputs'!$B$63 -> 0 | D8: ='Revenue Model'!D$28*'Model Inputs'!$B$63 -> 0 | E8: ='Revenue Model'!E$28*'Model Inputs'!$B$63 -> 58.08 | F8: ='Revenue Model'!F$28*'Model Inputs'!$B$63 -> 92.64 | G8: ='Revenue Model'!G$28*'Model Inputs'!$B$63 -> 144.48 | H8: ='Revenue Model'!H$28*'Model Inputs'!$B$63 -> 207.84 | I8: ='Revenue Model'!I$28*'Model Inputs'!$B$63 -> 270.96 | ... M8: ='Revenue Model'!M$28*'Model Inputs'!$B$63 -> 539.28 | N8: ='Revenue Model'!N$28*'Model Inputs'!$C$63 -> 461.88 | O8: ='Revenue Model'!O$28*'Model Inputs'!$C$63 -> 523.62 | P8: ='Revenue Model'!P$28*'Model Inputs'!$C$63 -> 594 | Q8: ='Revenue Model'!Q$28*'Model Inputs'!$C$63 -> 671.04 | R8: ='Revenue Model'!R$28*'Model Inputs'!$C$63 -> 752.76 | S8: ='Revenue Model'!S$28*'Model Inputs'!$C$63 -> 855.9 | T8: ='Revenue Model'!T$28*'Model Inputs'!$C$63 -> 968.22 | U8: ='Revenue Model'!U$28*'Model Inputs'!$C$63 -> 1080 | ... Y8: ='Revenue Model'!Y$28*'Model Inputs'!$C$63 -> 1623.96 | Z8: ='Revenue Model'!Z$28*'Model Inputs'!$D$63 -> 1393.56 | AA8: ='Revenue Model'!AA$28*'Model Inputs'!$D$63 -> 1523.48 | AB8: ='Revenue Model'!AB$28*'Model Inputs'!$D$63 -> 1652.84 | AC8: ='Revenue Model'!AC$28*'Model Inputs'!$D$63 -> 1803.2 | AD8: ='Revenue Model'!AD$28*'Model Inputs'!$D$63 -> 1952.86 | AE8: ='Revenue Model'!AE$28*'Model Inputs'!$D$63 -> 2105.88 | AF8: ='Revenue Model'!AF$28*'Model Inputs'!$D$63 -> 2282.84 | AG8: ='Revenue Model'!AG$28*'Model Inputs'!$D$63 -> 2459.1 | ... AL8: ='Revenue Model'!AL$28*'Model Inputs'!$D$63 -> 3262.98
A9: Support Automation | B9: ='Revenue Model'!B$28*'Model Inputs'!$B$64 -> 0 | C9: ='Revenue Model'!C$28*'Model Inputs'!$B$64 -> 0 | D9: ='Revenue Model'!D$28*'Model Inputs'!$B$64 -> 0 | E9: ='Revenue Model'!E$28*'Model Inputs'!$B$64 -> 0 | F9: ='Revenue Model'!F$28*'Model Inputs'!$B$64 -> 0 | G9: ='Revenue Model'!G$28*'Model Inputs'!$B$64 -> 0 | H9: ='Revenue Model'!H$28*'Model Inputs'!$B$64 -> 0 | I9: ='Revenue Model'!I$28*'Model Inputs'!$B$64 -> 0 | ... M9: ='Revenue Model'!M$28*'Model Inputs'!$B$64 -> 0 | N9: ='Revenue Model'!N$28*'Model Inputs'!$C$64 -> 153.96 | O9: ='Revenue Model'!O$28*'Model Inputs'!$C$64 -> 174.54 | P9: ='Revenue Model'!P$28*'Model Inputs'!$C$64 -> 198 | Q9: ='Revenue Model'!Q$28*'Model Inputs'!$C$64 -> 223.68 | R9: ='Revenue Model'!R$28*'Model Inputs'!$C$64 -> 250.92 | S9: ='Revenue Model'!S$28*'Model Inputs'!$C$64 -> 285.3 | T9: ='Revenue Model'!T$28*'Model Inputs'!$C$64 -> 322.74 | U9: ='Revenue Model'!U$28*'Model Inputs'!$C$64 -> 360 | ... Y9: ='Revenue Model'!Y$28*'Model Inputs'!$C$64 -> 541.32 | Z9: ='Revenue Model'!Z$28*'Model Inputs'!$D$64 -> 398.16 | AA9: ='Revenue Model'!AA$28*'Model Inputs'!$D$64 -> 435.28 | AB9: ='Revenue Model'!AB$28*'Model Inputs'!$D$64 -> 472.24 | AC9: ='Revenue Model'!AC$28*'Model Inputs'!$D$64 -> 515.2 | AD9: ='Revenue Model'!AD$28*'Model Inputs'!$D$64 -> 557.96 | AE9: ='Revenue Model'!AE$28*'Model Inputs'!$D$64 -> 601.68 | AF9: ='Revenue Model'!AF$28*'Model Inputs'!$D$64 -> 652.24 | AG9: ='Revenue Model'!AG$28*'Model Inputs'!$D$64 -> 702.6 | ... AL9: ='Revenue Model'!AL$28*'Model Inputs'!$D$64 -> 932.28
A10: Blockchain Gas (SOL) | B10: ='Revenue Model'!B$28*'Model Inputs'!$B$66 -> 0 | C10: ='Revenue Model'!C$28*'Model Inputs'!$B$66 -> 0 | D10: ='Revenue Model'!D$28*'Model Inputs'!$B$66 -> 0 | E10: ='Revenue Model'!E$28*'Model Inputs'!$B$66 -> 2.42 | F10: ='Revenue Model'!F$28*'Model Inputs'!$B$66 -> 3.86 | G10: ='Revenue Model'!G$28*'Model Inputs'!$B$66 -> 6.02 | H10: ='Revenue Model'!H$28*'Model Inputs'!$B$66 -> 8.66 | I10: ='Revenue Model'!I$28*'Model Inputs'!$B$66 -> 11.29 | ... M10: ='Revenue Model'!M$28*'Model Inputs'!$B$66 -> 22.47 | N10: ='Revenue Model'!N$28*'Model Inputs'!$C$66 -> 20.528 | O10: ='Revenue Model'!O$28*'Model Inputs'!$C$66 -> 23.272 | P10: ='Revenue Model'!P$28*'Model Inputs'!$C$66 -> 26.4 | Q10: ='Revenue Model'!Q$28*'Model Inputs'!$C$66 -> 29.824 | R10: ='Revenue Model'!R$28*'Model Inputs'!$C$66 -> 33.456 | S10: ='Revenue Model'!S$28*'Model Inputs'!$C$66 -> 38.04 | T10: ='Revenue Model'!T$28*'Model Inputs'!$C$66 -> 43.032 | U10: ='Revenue Model'!U$28*'Model Inputs'!$C$66 -> 48 | ... Y10: ='Revenue Model'!Y$28*'Model Inputs'!$C$66 -> 72.176 | Z10: ='Revenue Model'!Z$28*'Model Inputs'!$D$66 -> 59.724 | AA10: ='Revenue Model'!AA$28*'Model Inputs'!$D$66 -> 65.292 | AB10: ='Revenue Model'!AB$28*'Model Inputs'!$D$66 -> 70.836 | AC10: ='Revenue Model'!AC$28*'Model Inputs'!$D$66 -> 77.28 | AD10: ='Revenue Model'!AD$28*'Model Inputs'!$D$66 -> 83.694 | AE10: ='Revenue Model'!AE$28*'Model Inputs'!$D$66 -> 90.252 | AF10: ='Revenue Model'!AF$28*'Model Inputs'!$D$66 -> 97.836 | AG10: ='Revenue Model'!AG$28*'Model Inputs'!$D$66 -> 105.39 | ... AK10: ='Revenue Model'!AK$28*'Model Inputs'!$D$66 -> 138.546
A11: Payment Processing (2.9%) | B11: ='Revenue Model'!B$31*'Model Inputs'!$B$65 -> 0 | C11: ='Revenue Model'!C$31*'Model Inputs'!$B$65 -> 0 | D11: ='Revenue Model'!D$31*'Model Inputs'!$B$65 -> 0 | E11: ='Revenue Model'!E$31*'Model Inputs'!$B$65 -> 207.35 | F11: ='Revenue Model'!F$31*'Model Inputs'!$B$65 -> 310.5756 | G11: ='Revenue Model'!G$31*'Model Inputs'!$B$65 -> 519.09521 | H11: ='Revenue Model'!H$31*'Model Inputs'!$B$65 -> 738.12501 | I11: ='Revenue Model'!I$31*'Model Inputs'!$B$65 -> 962.28999 | ... AK11: ='Revenue Model'!AK$31*'Model Inputs'!$B$65 -> 20778.203 | AL11: ='Revenue Model'!AL$31*'Model Inputs'!$D$65 -> 19601.187
A12: STEP-FUNCTION COSTS (Tier-Based)
A13: Filebase Platform | B13: 0 | C13: 0 | D13: 0 | E13: ='Model Inputs'!$B$69 -> 1500 | F13: ='Model Inputs'!$B$69 -> 1500 | G13: ='Model Inputs'!$B$69 -> 1500 | H13: ='Model Inputs'!$B$69 -> 1500 | I13: ='Model Inputs'!$B$69 -> 1500 | J13: ='Model Inputs'!$B$69 -> 1500 | K13: ='Model Inputs'!$B$69 -> 1500 | L13: ='Model Inputs'!$B$69 -> 1500 | M13: ='Model Inputs'!$B$69 -> 1500 | N13: ='Model Inputs'!$C$69 -> 3000 | O13: ='Model Inputs'!$C$69 -> 3000 | P13: ='Model Inputs'!$C$69 -> 3000 | Q13: ='Model Inputs'!$C$69 -> 3000 | R13: ='Model Inputs'!$C$69 -> 3000 | S13: ='Model Inputs'!$C$69 -> 3000 | T13: ='Model Inputs'!$C$69 -> 3000 | U13: ='Model Inputs'!$C$69 -> 3000 | ... Y13: ='Model Inputs'!$C$69 -> 3000 | Z13: ='Model Inputs'!$D$69 -> 5000 | AA13: ='Model Inputs'!$D$69 -> 5000 | AB13: ='Model Inputs'!$D$69 -> 5000 | AC13: ='Model Inputs'!$D$69 -> 5000 | AD13: ='Model Inputs'!$D$69 -> 5000 | AE13: ='Model Inputs'!$D$69 -> 5000 | AF13: ='Model Inputs'!$D$69 -> 5000 | AG13: ='Model Inputs'!$D$69 -> 5000 | ... AK13: ='Model Inputs'!$D$69 -> 5000
A14: Blockchain RPC (Alchemy/Helius) | B14: 0 | C14: 0 | D14: 0 | E14: 0 | F14: 0 | G14: 0 | H14: 0 | I14: 0 | J14: 0 | K14: 0 | L14: 0 | M14: 0 | N14: 0 | O14: 0 | P14: 0 | Q14: ='Model Inputs'!$C$70 -> 249 | R14: ='Model Inputs'!$C$70 -> 249 | S14: ='Model Inputs'!$C$70 -> 249 | T14: ='Model Inputs'!$C$70 -> 249 | U14: ='Model Inputs'!$C$70 -> 249 | V14: ='Model Inputs'!$C$70 -> 249 | W14: ='Model Inputs'!$C$70 -> 249 | X14: ='Model Inputs'!$C$70 -> 249 | Y14: ='Model Inputs'!$C$70 -> 249 | Z14: ='Model Inputs'!$D$70 -> 499 | AA14: ='Model Inputs'!$D$70 -> 499 | AB14: ='Model Inputs'!$D$70 -> 499 | AC14: ='Model Inputs'!$D$70 -> 499 | AD14: ='Model Inputs'!$D$70 -> 499 | AE14: ='Model Inputs'!$D$70 -> 499 | AF14: ='Model Inputs'!$D$70 -> 499 | AG14: ='Model Inputs'!$D$70 -> 499 | ... AL14: ='Model Inputs'!$D$70 -> 499
A15: Monitoring | B15: 0 | C15: 0 | D15: 0 | E15: ='Model Inputs'!$B$71 -> 0 | F15: ='Model Inputs'!$B$71 -> 0 | G15: ='Model Inputs'!$B$71 -> 0 | H15: ='Model Inputs'!$B$71 -> 0 | I15: ='Model Inputs'!$B$71 -> 0 | J15: ='Model Inputs'!$B$71 -> 0 | K15: ='Model Inputs'!$B$71 -> 0 | L15: ='Model Inputs'!$B$71 -> 0 | M15: ='Model Inputs'!$B$71 -> 0 | N15: ='Model Inputs'!$C$71 -> 350 | O15: ='Model Inputs'!$C$71 -> 350 | P15: ='Model Inputs'!$C$71 -> 350 | Q15: ='Model Inputs'!$C$71 -> 350 | R15: ='Model Inputs'!$C$71 -> 350 | S15: ='Model Inputs'!$C$71 -> 350 | T15: ='Model Inputs'!$C$71 -> 350 | U15: ='Model Inputs'!$C$71 -> 350 | ... Y15: ='Model Inputs'!$C$71 -> 350 | Z15: ='Model Inputs'!$D$71 -> 600 | AA15: ='Model Inputs'!$D$71 -> 600 | AB15: ='Model Inputs'!$D$71 -> 600 | AC15: ='Model Inputs'!$D$71 -> 600 | AD15: ='Model Inputs'!$D$71 -> 600 | AE15: ='Model Inputs'!$D$71 -> 600 | AF15: ='Model Inputs'!$D$71 -> 600 | AG15: ='Model Inputs'!$D$71 -> 600 | ... AK15: ='Model Inputs'!$D$71 -> 600
A16: Transactional Email (SendGrid) | B16: 0 | C16: 0 | D16: 0 | E16: ='Model Inputs'!$B$73 -> 0 | F16: ='Model Inputs'!$B$73 -> 0 | G16: ='Model Inputs'!$B$73 -> 0 | H16: ='Model Inputs'!$B$73 -> 0 | I16: ='Model Inputs'!$B$73 -> 0 | J16: ='Model Inputs'!$B$73 -> 0 | K16: ='Model Inputs'!$B$73 -> 0 | L16: ='Model Inputs'!$B$73 -> 0 | M16: ='Model Inputs'!$B$73 -> 0 | N16: ='Model Inputs'!$C$73 -> 50 | O16: ='Model Inputs'!$C$73 -> 50 | P16: ='Model Inputs'!$C$73 -> 50 | Q16: ='Model Inputs'!$C$73 -> 50 | R16: ='Model Inputs'!$C$73 -> 50 | S16: ='Model Inputs'!$C$73 -> 50 | T16: ='Model Inputs'!$C$73 -> 50 | U16: ='Model Inputs'!$C$73 -> 50 | ... Y16: ='Model Inputs'!$C$73 -> 50 | Z16: ='Model Inputs'!$D$73 -> 90 | AA16: ='Model Inputs'!$D$73 -> 90 | AB16: ='Model Inputs'!$D$73 -> 90 | AC16: ='Model Inputs'!$D$73 -> 90 | AD16: ='Model Inputs'!$D$73 -> 90 | AE16: ='Model Inputs'!$D$73 -> 90 | AF16: ='Model Inputs'!$D$73 -> 90 | AG16: ='Model Inputs'!$D$73 -> 90 | ... AL16: ='Model Inputs'!$D$73 -> 90
A17: TRUE FIXED COSTS
A18: Base Compute | B18: 0 | C18: 0 | D18: 0 | E18: ='Model Inputs'!$B$76 -> 200 | F18: ='Model Inputs'!$B$76 -> 200 | G18: ='Model Inputs'!$B$76 -> 200 | H18: ='Model Inputs'!$B$76 -> 200 | I18: ='Model Inputs'!$B$76 -> 200 | J18: ='Model Inputs'!$B$76 -> 200 | K18: ='Model Inputs'!$B$76 -> 200 | L18: ='Model Inputs'!$B$76 -> 200 | M18: ='Model Inputs'!$B$76 -> 200 | N18: ='Model Inputs'!$C$76 -> 350 | O18: ='Model Inputs'!$C$76 -> 350 | P18: ='Model Inputs'!$C$76 -> 350 | Q18: ='Model Inputs'!$C$76 -> 350 | R18: ='Model Inputs'!$C$76 -> 350 | S18: ='Model Inputs'!$C$76 -> 350 | T18: ='Model Inputs'!$C$76 -> 350 | U18: ='Model Inputs'!$C$76 -> 350 | ... Y18: ='Model Inputs'!$C$76 -> 350 | Z18: ='Model Inputs'!$D$76 -> 500 | AA18: ='Model Inputs'!$D$76 -> 500 | AB18: ='Model Inputs'!$D$76 -> 500 | AC18: ='Model Inputs'!$D$76 -> 500 | AD18: ='Model Inputs'!$D$76 -> 500 | AE18: ='Model Inputs'!$D$76 -> 500 | AF18: ='Model Inputs'!$D$76 -> 500 | AG18: ='Model Inputs'!$D$76 -> 500 | ... AK18: ='Model Inputs'!$D$76 -> 500
A19: DR Infrastructure | B19: 0 | C19: 0 | D19: 0 | E19: ='Model Inputs'!$B$77 -> 200 | F19: ='Model Inputs'!$B$77 -> 200 | G19: ='Model Inputs'!$B$77 -> 200 | H19: ='Model Inputs'!$B$77 -> 200 | I19: ='Model Inputs'!$B$77 -> 200 | J19: ='Model Inputs'!$B$77 -> 200 | K19: ='Model Inputs'!$B$77 -> 200 | L19: ='Model Inputs'!$B$77 -> 200 | M19: ='Model Inputs'!$B$77 -> 200 | N19: ='Model Inputs'!$C$77 -> 300 | O19: ='Model Inputs'!$C$77 -> 300 | P19: ='Model Inputs'!$C$77 -> 300 | Q19: ='Model Inputs'!$C$77 -> 300 | R19: ='Model Inputs'!$C$77 -> 300 | S19: ='Model Inputs'!$C$77 -> 300 | T19: ='Model Inputs'!$C$77 -> 300 | U19: ='Model Inputs'!$C$77 -> 300 | ... Y19: ='Model Inputs'!$C$77 -> 300 | Z19: ='Model Inputs'!$D$77 -> 400 | AA19: ='Model Inputs'!$D$77 -> 400 | AB19: ='Model Inputs'!$D$77 -> 400 | AC19: ='Model Inputs'!$D$77 -> 400 | AD19: ='Model Inputs'!$D$77 -> 400 | AE19: ='Model Inputs'!$D$77 -> 400 | AF19: ='Model Inputs'!$D$77 -> 400 | AG19: ='Model Inputs'!$D$77 -> 400 | ... AK19: ='Model Inputs'!$D$77 -> 400
A20: Total COGS | B20: =SUM(B5:B11)+SUM(B13:B16)+SUM(B18:B19) -> 0 | C20: =SUM(C5:C11)+SUM(C13:C16)+SUM(C18:C19) -> 0 | D20: =SUM(D5:D11)+SUM(D13:D16)+SUM(D18:D19) -> 0 | E20: =SUM(E5:E11)+SUM(E13:E16)+SUM(E18:E19) -> 3193.93 | F20: =SUM(F5:F11)+SUM(F13:F16)+SUM(F18:F19) -> 3943.7156 | G20: =SUM(G5:G11)+SUM(G13:G16)+SUM(G18:G19) -> 5122.0752 | H20: =SUM(H5:H11)+SUM(H13:H16)+SUM(H18:H19) -> 6526.465 | I20: =SUM(I5:I11)+SUM(I13:I16)+SUM(I18:I19) -> 7931.5 | ... AK20: =SUM(AK5:AK11)+SUM(AK13:AK16)+SUM(AK18:AK19) -> 88735.079
A21: MARGIN ANALYSIS
A22: Gross Profit | B22: ='Revenue Model'!B$31-B20 -> 0 | C22: ='Revenue Model'!C$31-C20 -> 0 | D22: ='Revenue Model'!D$31-D20 -> 0 | E22: ='Revenue Model'!E$31-E20 -> 3956.07 | F22: ='Revenue Model'!F$31-F20 -> 6765.7878 | G22: ='Revenue Model'!G$31-G20 -> 12777.76 | H22: ='Revenue Model'!H$31-H20 -> 18926.121 | I22: ='Revenue Model'!I$31-I20 -> 25250.914 | ... AK22: ='Revenue Model'!AK$31-AK20 -> 627754.69 | AL22: ='Revenue Model'!AL$31-AL$18 -> 675903 | AM22: ='Revenue Model'!AM$31-AM$18 -> 0
A23: Gross Margin % | B23: =IF('Revenue Model'!B$31>0,B22/'Revenue Model'!B$31,0) -> 0 | C23: =IF('Revenue Model'!C$31>0,C22/'Revenue Model'!C$31,0) -> 0 | D23: =IF('Revenue Model'!D$31>0,D22/'Revenue Model'!D$31,0) -> 0 | E23: =IF('Revenue Model'!E$31>0,E22/'Revenue Model'!E$31,0) -> 0.5532965 | F23: =IF('Revenue Model'!F$31>0,F22/'Revenue Model'!F$31,0) -> 0.63175551 | G23: =IF('Revenue Model'!G$31>0,G22/'Revenue Model'!G$31,0) -> 0.71384791 | H23: =IF('Revenue Model'!H$31>0,H22/'Revenue Model'!H$31,0) -> 0.74358343 | I23: =IF('Revenue Model'!I$31>0,I22/'Revenue Model'!I$31,0) -> 0.76097278 | ... AK23: =IF('Revenue Model'!AK$31>0,AK22/'Revenue Model'!AK$31,0) -> 0.87615304 | AL23: =IF('Revenue Model'!AL$31>0,AL$20/'Revenue Model'!AL$31,0) -> 0 | AM23: =IF('Revenue Model'!AM$31>0,AM$20/'Revenue Model'!AM$31,0) -> 0
A26: MERCURY BANKING STARTUP PERKS - INFRASTRUCTURE DISCOUNTS
A28: Solution | B28: Category | C28: List Price | D28: Our Price | E28: Annual Savings | F28: Discount | G28: Notes
A29: Filebase | B29: IPFS Storage | C29: $1,200 | D29: $0 | E29: $1,200 | F29: 100% | G29: 12-month credits via Mercury Perks
A30: Datadog | B30: Monitoring | C30: $1,800 | D30: $0 | E30: $1,800 | F30: 100% | G30: Startup program (Y1 free)
A31: Alchemy | B31: Blockchain RPC | C31: $2,500 | D31: $0 | E31: $2,500 | F31: 100% | G31: Early Stage program (Y1-Y3 tiered)
A32: SendGrid | B32: Email | C32: $600 | D32: $0 | E32: $600 | F32: 100% | G32: 12-month credits (backup/reserve)
A33: TOTAL Y1 SAVINGS | E33: $6,100 | G33: Primary RPC - no discount available
A34: Stripe | B34: Payments | C34: 2.9% | D34: 2.9% | E34: $0 | F34: 0% | G34: Standard rate - no startup discount
A35: INFRASTRUCTURE STACK SUMMARY (Monthly)
A37: Component | B37: Solution | C37: Y1 | D37: Y2 | E37: Y3 | F37: Notes
A38: Storage Infrastructure | B38: Filebase | C38: $1,500 | D38: $3,000 | E38: $5,000 | F38: Mercury credit Y1
A39: Blockchain RPC | B39: Alchemy → Helius | C39: $0 | D39: $249 | E39: $499 | F39: Alchemy credit covers Y1
A40: Monitoring | B40: Datadog | C40: $0 | D40: $350 | E40: $600 | F40: Mercury credit Y1
A41: Transactional Email | B41: SendGrid | C41: $0 | D41: $50 | E41: $90 | F41: Free tier Y1 | G41: Justification
A42: Base Compute | B42: Vercel/AWS | C42: $200 | D42: $350 | E42: $500 | G42: Dedicated IPFS gateways, 99.9% SLA
A43: DR Infrastructure | B43: Multi-region | C43: $200 | D43: $300 | E43: $400 | G43: Solana-optimized, staked connections
A44: MONTHLY TOTAL | C44: $1,900 | D44: $4,299 | E44: $7,089 | F44: Startup → Pro | G44: APM, logs, infrastructure metrics
A46: Notes: | F46: Standard | G46: PCI compliant, subscription billing
...

Sheet Staffing Plan
A1: STAFFING PLAN - 36-MONTH DETAIL
A3: Role | B3: Dept | C3: Annual Salary | D3: Start Month | E3: Loading Type | F3: Y1M1 | G3: Y1M2 | H3: Y1M3 | I3: Y1M4 | J3: Y1M5 | K3: Y1M6 | L3: Y1M7 | M3: Y1M8 | N3: Y1M9 | O3: Y1M10 | P3: Y1M11 | Q3: Y1M12 | R3: Y2M1 | S3: Y2M2 | T3: Y2M3 | U3: Y2M4 | V3: Y2M5 | W3: Y2M6 | X3: Y2M7 | Y3: Y2M8 | Z3: Y2M9 | AA3: Y2M10 | AB3: Y2M11 | AC3: Y2M12 | AD3: Y3M1 | AE3: Y3M2 | AF3: Y3M3 | AG3: Y3M4 | AH3: Y3M5 | AI3: Y3M6 | AJ3: Y3M7 | AK3: Y3M8 | AL3: Y3M9 | AM3: Y3M10 | AN3: Y3M11 | AO3: Y3M12
A4: CEO / Head of Sales | B4: Executive | C4: 90000 | D4: 1 | E4: founder | F4: =IF(1>=$D4,$C4/12,0) -> 7500 | G4: =IF(2>=$D4,$C4/12,0) -> 7500 | H4: =IF(3>=$D4,$C4/12,0) -> 7500 | I4: =IF(4>=$D4,$C4/12,0) -> 7500 | J4: =IF(5>=$D4,$C4/12,0) -> 7500 | K4: =IF(6>=$D4,$C4/12,0) -> 7500 | L4: =IF(7>=$D4,$C4/12,0) -> 7500 | M4: =IF(8>=$D4,$C4/12,0) -> 7500 | N4: =IF(9>=$D4,$C4/12,0) -> 7500 | O4: =IF(10>=$D4,$C4/12,0) -> 7500 | P4: =IF(11>=$D4,$C4/12,0) -> 7500 | Q4: =IF(12>=$D4,$C4/12,0) -> 7500 | R4: =IF(13>=$D4,$C4/12,0) -> 7500 | S4: =IF(14>=$D4,$C4/12,0) -> 7500 | T4: =IF(15>=$D4,$C4/12,0) -> 7500 | U4: =IF(16>=$D4,$C4/12,0) -> 7500 | V4: =IF(17>=$D4,$C4/12,0) -> 7500 | W4: =IF(18>=$D4,$C4/12,0) -> 7500 | X4: =IF(19>=$D4,$C4/12,0) -> 7500 | Y4: =IF(20>=$D4,$C4/12,0) -> 7500 | Z4: =IF(21>=$D4,$C4/12,0) -> 7500 | AA4: =IF(22>=$D4,$C4/12,0) -> 7500 | AB4: =IF(23>=$D4,$C4/12,0) -> 7500 | AC4: =IF(24>=$D4,$C4/12,0) -> 7500 | AD4: =IF(25>=$D4,$C4/12,0) -> 7500 | AE4: =IF(26>=$D4,$C4/12,0) -> 7500 | AF4: =IF(27>=$D4,$C4/12,0) -> 7500 | AG4: =IF(28>=$D4,$C4/12,0) -> 7500 | AH4: =IF(29>=$D4,$C4/12,0) -> 7500 | AI4: =IF(30>=$D4,$C4/12,0) -> 7500 | AJ4: =IF(31>=$D4,$C4/12,0) -> 7500 | AK4: =IF(32>=$D4,$C4/12,0) -> 7500 | AL4: =IF(33>=$D4,$C4/12,0) -> 7500 | AM4: =IF(34>=$D4,$C4/12,0) -> 7500 | AN4: =IF(35>=$D4,$C4/12,0) -> 7500 | AO4: =IF(36>=$D4,$C4/12,0) -> 7500
A5: CTO / Sr. Full Stack | B5: Engineering | C5: 90000 | D5: 1 | E5: founder | F5: =IF(1>=$D5,$C5/12,0) -> 7500 | G5: =IF(2>=$D5,$C5/12,0) -> 7500 | H5: =IF(3>=$D5,$C5/12,0) -> 7500 | I5: =IF(4>=$D5,$C5/12,0) -> 7500 | J5: =IF(5>=$D5,$C5/12,0) -> 7500 | K5: =IF(6>=$D5,$C5/12,0) -> 7500 | L5: =IF(7>=$D5,$C5/12,0) -> 7500 | M5: =IF(8>=$D5,$C5/12,0) -> 7500 | N5: =IF(9>=$D5,$C5/12,0) -> 7500 | O5: =IF(10>=$D5,$C5/12,0) -> 7500 | P5: =IF(11>=$D5,$C5/12,0) -> 7500 | Q5: =IF(12>=$D5,$C5/12,0) -> 7500 | R5: =IF(13>=$D5,$C5/12,0) -> 7500 | S5: =IF(14>=$D5,$C5/12,0) -> 7500 | T5: =IF(15>=$D5,$C5/12,0) -> 7500 | U5: =IF(16>=$D5,$C5/12,0) -> 7500 | V5: =IF(17>=$D5,$C5/12,0) -> 7500 | W5: =IF(18>=$D5,$C5/12,0) -> 7500 | X5: =IF(19>=$D5,$C5/12,0) -> 7500 | Y5: =IF(20>=$D5,$C5/12,0) -> 7500 | Z5: =IF(21>=$D5,$C5/12,0) -> 7500 | AA5: =IF(22>=$D5,$C5/12,0) -> 7500 | AB5: =IF(23>=$D5,$C5/12,0) -> 7500 | AC5: =IF(24>=$D5,$C5/12,0) -> 7500 | AD5: =IF(25>=$D5,$C5/12,0) -> 7500 | AE5: =IF(26>=$D5,$C5/12,0) -> 7500 | AF5: =IF(27>=$D5,$C5/12,0) -> 7500 | AG5: =IF(28>=$D5,$C5/12,0) -> 7500 | AH5: =IF(29>=$D5,$C5/12,0) -> 7500 | AI5: =IF(30>=$D5,$C5/12,0) -> 7500 | AJ5: =IF(31>=$D5,$C5/12,0) -> 7500 | AK5: =IF(32>=$D5,$C5/12,0) -> 7500 | AL5: =IF(33>=$D5,$C5/12,0) -> 7500 | AM5: =IF(34>=$D5,$C5/12,0) -> 7500 | AN5: =IF(35>=$D5,$C5/12,0) -> 7500 | AO5: =IF(36>=$D5,$C5/12,0) -> 7500
A6: Sr. Protocol Engineer | B6: Engineering | C6: 90000 | D6: 1 | E6: intlContractor | F6: =IF(1>=$D6,$C6/12,0) -> 7500 | G6: =IF(2>=$D6,$C6/12,0) -> 7500 | H6: =IF(3>=$D6,$C6/12,0) -> 7500 | I6: =IF(4>=$D6,$C6/12,0) -> 7500 | J6: =IF(5>=$D6,$C6/12,0) -> 7500 | K6: =IF(6>=$D6,$C6/12,0) -> 7500 | L6: =IF(7>=$D6,$C6/12,0) -> 7500 | M6: =IF(8>=$D6,$C6/12,0) -> 7500 | N6: =IF(9>=$D6,$C6/12,0) -> 7500 | O6: =IF(10>=$D6,$C6/12,0) -> 7500 | P6: =IF(11>=$D6,$C6/12,0) -> 7500 | Q6: =IF(12>=$D6,$C6/12,0) -> 7500 | R6: =IF(13>=$D6,$C6/12,0) -> 7500 | S6: =IF(14>=$D6,$C6/12,0) -> 7500 | T6: =IF(15>=$D6,$C6/12,0) -> 7500 | U6: =IF(16>=$D6,$C6/12,0) -> 7500 | V6: =IF(17>=$D6,$C6/12,0) -> 7500 | W6: =IF(18>=$D6,$C6/12,0) -> 7500 | X6: =IF(19>=$D6,$C6/12,0) -> 7500 | Y6: =IF(20>=$D6,$C6/12,0) -> 7500 | Z6: =IF(21>=$D6,$C6/12,0) -> 7500 | AA6: =IF(22>=$D6,$C6/12,0) -> 7500 | AB6: =IF(23>=$D6,$C6/12,0) -> 7500 | AC6: =IF(24>=$D6,$C6/12,0) -> 7500 | AD6: =IF(25>=$D6,$C6/12,0) -> 7500 | AE6: =IF(26>=$D6,$C6/12,0) -> 7500 | AF6: =IF(27>=$D6,$C6/12,0) -> 7500 | AG6: =IF(28>=$D6,$C6/12,0) -> 7500 | AH6: =IF(29>=$D6,$C6/12,0) -> 7500 | AI6: =IF(30>=$D6,$C6/12,0) -> 7500 | AJ6: =IF(31>=$D6,$C6/12,0) -> 7500 | AK6: =IF(32>=$D6,$C6/12,0) -> 7500 | AL6: =IF(33>=$D6,$C6/12,0) -> 7500 | AM6: =IF(34>=$D6,$C6/12,0) -> 7500 | AN6: =IF(35>=$D6,$C6/12,0) -> 7500 | AO6: =IF(36>=$D6,$C6/12,0) -> 7500
A7: Backend Security Eng | B7: Engineering | C7: 80000 | D7: 8 | E7: intlContractor | F7: =IF(1>=$D7,$C7/12,0) -> 0 | G7: =IF(2>=$D7,$C7/12,0) -> 0 | H7: =IF(3>=$D7,$C7/12,0) -> 0 | I7: =IF(4>=$D7,$C7/12,0) -> 0 | J7: =IF(5>=$D7,$C7/12,0) -> 0 | K7: =IF(6>=$D7,$C7/12,0) -> 0 | L7: =IF(7>=$D7,$C7/12,0) -> 0 | M7: =IF(8>=$D7,$C7/12,0) -> 6666.6667 | N7: =IF(9>=$D7,$C7/12,0) -> 6666.6667 | O7: =IF(10>=$D7,$C7/12,0) -> 6666.6667 | P7: =IF(11>=$D7,$C7/12,0) -> 6666.6667 | Q7: =IF(12>=$D7,$C7/12,0) -> 6666.6667 | R7: =IF(13>=$D7,$C7/12,0) -> 6666.6667 | S7: =IF(14>=$D7,$C7/12,0) -> 6666.6667 | T7: =IF(15>=$D7,$C7/12,0) -> 6666.6667 | U7: =IF(16>=$D7,$C7/12,0) -> 6666.6667 | V7: =IF(17>=$D7,$C7/12,0) -> 6666.6667 | W7: =IF(18>=$D7,$C7/12,0) -> 6666.6667 | X7: =IF(19>=$D7,$C7/12,0) -> 6666.6667 | Y7: =IF(20>=$D7,$C7/12,0) -> 6666.6667 | Z7: =IF(21>=$D7,$C7/12,0) -> 6666.6667 | AA7: =IF(22>=$D7,$C7/12,0) -> 6666.6667 | AB7: =IF(23>=$D7,$C7/12,0) -> 6666.6667 | AC7: =IF(24>=$D7,$C7/12,0) -> 6666.6667 | AD7: =IF(25>=$D7,$C7/12,0) -> 6666.6667 | AE7: =IF(26>=$D7,$C7/12,0) -> 6666.6667 | AF7: =IF(27>=$D7,$C7/12,0) -> 6666.6667 | AG7: =IF(28>=$D7,$C7/12,0) -> 6666.6667 | AH7: =IF(29>=$D7,$C7/12,0) -> 6666.6667 | AI7: =IF(30>=$D7,$C7/12,0) -> 6666.6667 | AJ7: =IF(31>=$D7,$C7/12,0) -> 6666.6667 | AK7: =IF(32>=$D7,$C7/12,0) -> 6666.6667 | AL7: =IF(33>=$D7,$C7/12,0) -> 6666.6667 | AM7: =IF(34>=$D7,$C7/12,0) -> 6666.6667 | AN7: =IF(35>=$D7,$C7/12,0) -> 6666.6667 | AO7: =IF(36>=$D7,$C7/12,0) -> 6666.6667
A8: Developer Advocate | B8: Marketing | C8: 85000 | D8: 99 | E8: us | F8: =IF(1>=$D8,$C8/12,0) -> 0 | G8: =IF(2>=$D8,$C8/12,0) -> 0 | H8: =IF(3>=$D8,$C8/12,0) -> 0 | I8: =IF(4>=$D8,$C8/12,0) -> 0 | J8: =IF(5>=$D8,$C8/12,0) -> 0 | K8: =IF(6>=$D8,$C8/12,0) -> 0 | L8: =IF(7>=$D8,$C8/12,0) -> 0 | M8: =IF(8>=$D8,$C8/12,0) -> 0 | N8: =IF(9>=$D8,$C8/12,0) -> 0 | O8: =IF(10>=$D8,$C8/12,0) -> 0 | P8: =IF(11>=$D8,$C8/12,0) -> 0 | Q8: =IF(12>=$D8,$C8/12,0) -> 0 | R8: =IF(13>=$D8,$C8/12,0) -> 0 | S8: =IF(14>=$D8,$C8/12,0) -> 0 | T8: =IF(15>=$D8,$C8/12,0) -> 0 | U8: =IF(16>=$D8,$C8/12,0) -> 0 | V8: =IF(17>=$D8,$C8/12,0) -> 0 | W8: =IF(18>=$D8,$C8/12,0) -> 0 | X8: =IF(19>=$D8,$C8/12,0) -> 0 | Y8: =IF(20>=$D8,$C8/12,0) -> 0 | Z8: =IF(21>=$D8,$C8/12,0) -> 0 | AA8: =IF(22>=$D8,$C8/12,0) -> 0 | AB8: =IF(23>=$D8,$C8/12,0) -> 0 | AC8: =IF(24>=$D8,$C8/12,0) -> 0 | AD8: =IF(25>=$D8,$C8/12,0) -> 0 | AE8: =IF(26>=$D8,$C8/12,0) -> 0 | AF8: =IF(27>=$D8,$C8/12,0) -> 0 | AG8: =IF(28>=$D8,$C8/12,0) -> 0 | AH8: =IF(29>=$D8,$C8/12,0) -> 0 | AI8: =IF(30>=$D8,$C8/12,0) -> 0 | AJ8: =IF(31>=$D8,$C8/12,0) -> 0 | AK8: =IF(32>=$D8,$C8/12,0) -> 0 | AL8: =IF(33>=$D8,$C8/12,0) -> 0 | AM8: =IF(34>=$D8,$C8/12,0) -> 0 | AN8: =IF(35>=$D8,$C8/12,0) -> 0 | AO8: =IF(36>=$D8,$C8/12,0) -> 0
A9: Customer Success Lead | B9: CS | C9: 65000 | D9: 10 | E9: us | F9: =IF(1>=$D9,$C9/12,0) -> 0 | G9: =IF(2>=$D9,$C9/12,0) -> 0 | H9: =IF(3>=$D9,$C9/12,0) -> 0 | I9: =IF(4>=$D9,$C9/12,0) -> 0 | J9: =IF(5>=$D9,$C9/12,0) -> 0 | K9: =IF(6>=$D9,$C9/12,0) -> 0 | L9: =IF(7>=$D9,$C9/12,0) -> 0 | M9: =IF(8>=$D9,$C9/12,0) -> 0 | N9: =IF(9>=$D9,$C9/12,0) -> 0 | O9: =IF(10>=$D9,$C9/12,0) -> 5416.6667 | P9: =IF(11>=$D9,$C9/12,0) -> 5416.6667 | Q9: =IF(12>=$D9,$C9/12,0) -> 5416.6667 | R9: =IF(13>=$D9,$C9/12,0) -> 5416.6667 | S9: =IF(14>=$D9,$C9/12,0) -> 5416.6667 | T9: =IF(15>=$D9,$C9/12,0) -> 5416.6667 | U9: =IF(16>=$D9,$C9/12,0) -> 5416.6667 | V9: =IF(17>=$D9,$C9/12,0) -> 5416.6667 | W9: =IF(18>=$D9,$C9/12,0) -> 5416.6667 | X9: =IF(19>=$D9,$C9/12,0) -> 5416.6667 | Y9: =IF(20>=$D9,$C9/12,0) -> 5416.6667 | Z9: =IF(21>=$D9,$C9/12,0) -> 5416.6667 | AA9: =IF(22>=$D9,$C9/12,0) -> 5416.6667 | AB9: =IF(23>=$D9,$C9/12,0) -> 5416.6667 | AC9: =IF(24>=$D9,$C9/12,0) -> 5416.6667 | AD9: =IF(25>=$D9,$C9/12,0) -> 5416.6667 | AE9: =IF(26>=$D9,$C9/12,0) -> 5416.6667 | AF9: =IF(27>=$D9,$C9/12,0) -> 5416.6667 | AG9: =IF(28>=$D9,$C9/12,0) -> 5416.6667 | AH9: =IF(29>=$D9,$C9/12,0) -> 5416.6667 | AI9: =IF(30>=$D9,$C9/12,0) -> 5416.6667 | AJ9: =IF(31>=$D9,$C9/12,0) -> 5416.6667 | AK9: =IF(32>=$D9,$C9/12,0) -> 5416.6667 | AL9: =IF(33>=$D9,$C9/12,0) -> 5416.6667 | AM9: =IF(34>=$D9,$C9/12,0) -> 5416.6667 | AN9: =IF(35>=$D9,$C9/12,0) -> 5416.6667 | AO9: =IF(36>=$D9,$C9/12,0) -> 5416.6667
